Watching for file changes with StatReloader
"GET / HTTP/1.1" 302 0
"GET /login/?next=/ HTTP/1.1" 200 2230
"GET /static/images/login_image.jpg HTTP/1.1" 200 1969029
Not Found: /favicon.ico
"GET /favicon.ico HTTP/1.1" 404 2915
"GET /signup/ HTTP/1.1" 200 2217
"POST /signup/ HTTP/1.1" 302 0
"GET /login/ HTTP/1.1" 200 2230
"POST /login/ HTTP/1.1" 302 0
Internal Server Error: /
Traceback (most recent call last):
  File "C:\Users\91730\anaconda3\lib\site-packages\django\core\handlers\exception.py", line 55, in inner
    response = get_response(request)
  File "C:\Users\91730\anaconda3\lib\site-packages\django\core\handlers\base.py", line 197, in _get_response
    response = wrapped_callback(request, *callback_args, **callback_kwargs)
  File "C:\Users\91730\anaconda3\lib\site-packages\django\contrib\auth\decorators.py", line 23, in _wrapper_view
    return view_func(request, *args, **kwargs)
  File "C:\Users\91730\PycharmProjects\django_calculator\django_calci\accounts\views.py", line 36, in dashboard
    return render(request, 'accounts/dashboard.html')
  File "C:\Users\91730\anaconda3\lib\site-packages\django\shortcuts.py", line 24, in render
    content = loader.render_to_string(template_name, context, request, using=using)
  File "C:\Users\91730\anaconda3\lib\site-packages\django\template\loader.py", line 62, in render_to_string
    return template.render(context, request)
  File "C:\Users\91730\anaconda3\lib\site-packages\django\template\backends\django.py", line 61, in render
    return self.template.render(context)
  File "C:\Users\91730\anaconda3\lib\site-packages\django\template\base.py", line 175, in render
    return self._render(context)
  File "C:\Users\91730\anaconda3\lib\site-packages\django\template\base.py", line 167, in _render
    return self.nodelist.render(context)
  File "C:\Users\91730\anaconda3\lib\site-packages\django\template\base.py", line 1005, in render
    return SafeString("".join([node.render_annotated(context) for node in self]))
  File "C:\Users\91730\anaconda3\lib\site-packages\django\template\base.py", line 1005, in <listcomp>
    return SafeString("".join([node.render_annotated(context) for node in self]))
  File "C:\Users\91730\anaconda3\lib\site-packages\django\template\base.py", line 966, in render_annotated
    return self.render(context)
  File "C:\Users\91730\anaconda3\lib\site-packages\django\template\defaulttags.py", line 471, in render
    url = reverse(view_name, args=args, kwargs=kwargs, current_app=current_app)
  File "C:\Users\91730\anaconda3\lib\site-packages\django\urls\base.py", line 88, in reverse
    return resolver._reverse_with_prefix(view, prefix, *args, **kwargs)
  File "C:\Users\91730\anaconda3\lib\site-packages\django\urls\resolvers.py", line 828, in _reverse_with_prefix
    raise NoReverseMatch(msg)
django.urls.exceptions.NoReverseMatch: Reverse for 'basic_calculator' not found. 'basic_calculator' is not a valid view function or pattern name.
"GET / HTTP/1.1" 500 122139
"GET /signout HTTP/1.1" 301 0
"GET /signout/ HTTP/1.1" 200 2230
"GET /static/images/login_image.jpg HTTP/1.1" 304 0
